<?xml version="1.0" encoding="utf-8"?>
<!-- =================================================================================== -->
<!-- |    This document was autogenerated by xacro from siriusmid.urdf.xacro           | -->
<!-- |    EDITING THIS FILE BY HAND IS NOT RECOMMENDED                                 | -->
<!-- =================================================================================== -->
<robot name="siriusmid">
  <!-- arm link 1 position-->
  <!-- arm link 2 position-->
  <!-- arm link 3 position-->
  <!-- arm link 4 position-->
  <!-- arm link 5 position-->
  <!-- arm link 6 position-->
  <!-- Defining the colors used in this robot -->
  <material name="Black">
    <color rgba="0 0 0 1"/>
  </material>
  <material name="Yellow">
    <color rgba="0.854 0.976 0.14 0.8"/>
  </material>
  <material name="White">
    <color rgba="1 1 1 1"/>
  </material>
  <material name="Pink">
    <color rgba="0.96 0.15 0.568 0.8"/>
  </material>
  <material name="Blue">
    <color rgba="0 0 1 1"/>
  </material>
  <material name="Red">
    <color rgba="1 0 0 1"/>
  </material>
  <material name="GreenSky">
    <color rgba="0.149 0.976 0.941 0.8"/>
  </material>

  <!-- Now we can start using the macros included above to define the actual Siriusmid -->
  <!-- BASE LINK -->
  <!-- floating type is supported in older versions of Gazebo. In new Gazebo if a link has no parent, it is supposed to be attached to a floating joint -->
  <!-- Floating-base Joint -->
  <!-- <link name="world"/>
  <joint name="floating_base_joint" type="floating">
    <origin rpy="0 0 0" xyz="0 0 0"/>
    <parent link="world"/>
    <child link="base_link"/>
  </joint>
  <joint name="floating_base" type="fixed">
    <origin rpy="0 0 0" xyz="0 0 0"/>
    <parent link="base_link"/>
    <child link="body_link"/>
  </joint> -->
  <!-- <link name="base_link"/> -->
  <!-- body link -->
  <link name="body_link">
    <inertial>
      <origin rpy="0 0 0" xyz="4.0393E-05 -2.1734E-06 -0.00063565"/>
      <mass value="5.283"/>
      <inertia ixx="0.028454" ixy="-5.9775E-08" ixz="-0.00050774" iyy="0.15791" iyz="-1.7886E-08" izz="0.17219"/>
    </inertial>
    <visual>
      <origin rpy="1.5704 0 0" xyz=" 0 0 0"/>
      <geometry>
        <mesh filename="package://siriusmid_description/meshes/body_link.STL"/>
      </geometry>
      <material name="Pink"/>
    </visual>
    <collision>
      <origin rpy="0 0 0" xyz="0 0 0"/>
      <geometry>
        <mesh filename="package://siriusmid_description/meshes/body_link.STL"/>
      </geometry>
    </collision>
  </link>

  <!-- Joints -->
  <!-- abad assembly joint -->
  <!-- Links -->
  <!-- abad link -->
  <link name="lf_abad_link">
    <inertial>
      <origin rpy="0 0 0" xyz="-0.0012806 4.3563E-08 0.049958"/>
      <mass value="0.92607"/>
      <inertia ixx="0.00098647" ixy="-7.0392E-11" ixz="6.4987E-06" iyy="0.00071554" iyz="1.2357E-10" izz="0.00065157"/>
    </inertial>
    <visual>
      <origin rpy="0 0  0 " xyz="0 0 0"/>
      <geometry>
        <mesh filename="package://siriusmid_description/meshes/lf_abad_link.STL"/>
      </geometry>
      <material name="Black"/>
    </visual>
    <collision>
      <origin rpy="0 0 0 " xyz="0 0 0"/>
      <geometry>
        <mesh filename="package://siriusmid_description/meshes/lf_abad_link.STL"/>
      </geometry>
    </collision>
  </link>
  <!-- name: lf,lr,rf,rr -->
  <link name="lf_hip_link">
    <inertial>
      <origin rpy="0 0 0" xyz="0.027042 -1.7816E-10 0.028552"/>
      <mass value="1.22"/>
      <inertia ixx="0.001198" ixy="4.6672E-11" ixz="0.00095291" iyy="0.0068604" iyz="2.0712E-12" izz="0.0068553"/>
    </inertial>
    <visual>
      <origin rpy="0 0  0 " xyz="0 0 0"/>
      <geometry>
        <mesh filename="package://siriusmid_description/meshes/lf_hip_link.STL"/>
      </geometry>
      <material name="GreenSky"/>
    </visual>
    <collision>
      <origin rpy="0 0 0 " xyz="0 0 0"/>
      <geometry>
        <mesh filename="package://siriusmid_description/meshes/lf_hip_link.STL"/>
      </geometry>
    </collision>
  </link>
  <!-- Lower leg link -->
  <!-- name: lf,lr,rf,rr -->
  <link name="lf_knee_link">
    <inertial>
      <origin rpy="0 0 0" xyz="0.11612 -0.0066095 -4.5982E-08"/>
      <mass value="0.19509"/>
      <inertia ixx="0.00010142" ixy="-0.00027114" ixz="2.9242E-09" iyy="0.0024964" iyz="2.6632E-09" izz="0.0025805"/>
    </inertial>
    <visual>
      <origin rpy="0 0  0 " xyz="0 0 0"/>
      <geometry>
        <mesh filename="package://siriusmid_description/meshes/lf_knee_link.STL"/>
      </geometry>
      <material name="Blue"/>
    </visual>
    <collision>
      <origin rpy="0 0 0 " xyz="0 0 0"/>
      <geometry>
        <mesh filename="package://siriusmid_description/meshes/lf_knee_link.STL"/>
      </geometry>
    </collision>
  </link>
  <!-- Links -->
  <!-- Foot link -->
  <link name="lf_foot">
    <collision>
      <origin rpy="0 0 0" xyz="0 0 0"/>
      <geometry>
        <sphere radius="0.02175"/>
      </geometry>
    </collision>
    <visual>
      <geometry>
        <sphere radius="0.02175"/>
      </geometry>
      <material name="Red"/>
    </visual>
    <inertial>
      <origin rpy="0 0 0" xyz="0 0 0"/>
      <mass value="0.003"/>
      <inertia ixx="0." ixy="0" ixz="0" iyy="0" iyz="0" izz="0"/>
    </inertial>
  </link>
  <!-- Hip assembly -->
  <transmission name="lf_abad_trans">
    <type>transmission_interface/SimpleTransmission</type>
    <joint name="lf_abad_joint">
      <hardwareInterface>hardware_interface/EffortJointInterface</hardwareInterface>
    </joint>
    <actuator name="lf_haa_motor">
      <mechanicalReduction>1</mechanicalReduction>
    </actuator>
  </transmission>
  <!-- Upper leg -->
  <transmission name="lf_hip_trans">
    <type>transmission_interface/SimpleTransmission</type>
    <joint name="lf_hip_joint">
      <hardwareInterface>hardware_interface/EffortJointInterface</hardwareInterface>
    </joint>
    <actuator name="lf_hip_motor">
      <mechanicalReduction>1</mechanicalReduction>
    </actuator>
  </transmission>
  <!-- Lower leg -->
  <transmission name="lf_knee_trans">
    <type>transmission_interface/SimpleTransmission</type>
    <joint name="lf_knee_joint">
      <hardwareInterface>hardware_interface/EffortJointInterface</hardwareInterface>
    </joint>
    <actuator name="lf_knee_motor">
      <mechanicalReduction>1</mechanicalReduction>
    </actuator>
  </transmission>

  <!-- Joints -->
  <!-- abad assembly joint -->
  <joint name="rf_abad_joint" type="revolute">
    <parent link="body_link"/>
    <child link="rf_abad_link"/>
    <origin rpy="-1.5708 0 -1.5708" xyz="0.216 -0.055 0"/>
    <axis xyz="0 0 -1"/>
    <limit effort="25" lower="-2.88" upper="2.88" velocity="15"/>
    <!-- soft limits  keep the motor in safety mode-->
    <safety_controller k_position="500" k_velocity="5" soft_lower_limit="-2.78" soft_upper_limit="2.78"/>
  </joint>
  <!-- Upper leg joint -->
  <joint name="rf_hip_joint" type="revolute">
    <parent link="rf_abad_link"/>
    <child link="rf_hip_link"/>
    <origin rpy="1.5708 0 1.5708" xyz="0.09355 0 0.052"/>
    <axis xyz="0 0 1"/>
    <limit effort="25" lower="-2.88" upper="2.88" velocity="15"/>
    <!-- soft limits  keep the motor in safety mode-->
    <safety_controller k_position="500" k_velocity="5" soft_lower_limit="-2.78" soft_upper_limit="2.78"/>
  </joint>
  <!-- Lower leg joint -->
  <joint name="rf_knee_joint" type="revolute">
    <parent link="rf_hip_link"/>
    <child link="rf_knee_link"/>
    <origin rpy="0 0 0" xyz="0.269 0 0"/>
    <axis xyz="0 0 -1"/>
    <limit effort="25" lower="-2.88" upper="2.88" velocity="15"/>
    <!-- soft limits  keep the motor in safety mode-->
    <safety_controller k_position="500" k_velocity="5" soft_lower_limit="-2.78" soft_upper_limit="2.78"/>
  </joint>
    <joint name="lf_abad_joint" type="revolute">
    <parent link="body_link"/>
    <child link="lf_abad_link"/>
    <origin rpy="1.5708 0 1.5708" xyz="0.216 0.055 0"/>
    <axis xyz="0 0 -1"/>
    <limit effort="25" lower="-2.88" upper="2.88" velocity="15"/>
    <!-- soft limits  keep the motor in safety mode-->
    <safety_controller k_position="500" k_velocity="5" soft_lower_limit="-2.78" soft_upper_limit="2.78"/>
  </joint>
  <!-- Upper leg joint -->
  <joint name="lf_hip_joint" type="revolute">
    <parent link="lf_abad_link"/>
    <child link="lf_hip_link"/>
    <origin rpy="1.5708 0 -1.5708" xyz="0.09355 0 0.052"/>
    <axis xyz="0 0 1"/>
    <limit effort="25" lower="-2.88" upper="2.88" velocity="15"/>
    <!-- soft limits  keep the motor in safety mode-->
    <safety_controller k_position="500" k_velocity="5" soft_lower_limit="-2.78" soft_upper_limit="2.78"/>
  </joint>
  <!-- Lower leg joint -->
  <joint name="lf_knee_joint" type="revolute">
    <parent link="lf_hip_link"/>
    <child link="lf_knee_link"/>
    <origin rpy="0 0 0" xyz="0.269 0 0"/>
    <axis xyz="0 0 -1"/>
    <limit effort="25" lower="-2.88" upper="2.88" velocity="15"/>
    <!-- soft limits  keep the motor in safety mode-->
    <safety_controller k_position="500" k_velocity="5" soft_lower_limit="-2.78" soft_upper_limit="2.78"/>
  </joint>
  <!-- foot joint-->
  <joint name="lf_foot_joint" type="fixed">
    <origin rpy="1.57079632679 0 -1.57079632679" xyz="0.271 0 0"/>
    <parent link="lf_knee_link"/>
    <child link="lf_foot"/>
  </joint>

  <!-- foot joint-->
  <joint name="rf_foot_joint" type="fixed">
    <origin rpy="1.57079632679 0 -1.57079632679" xyz="0.271 0 0"/>
    <parent link="rf_knee_link"/>
    <child link="rf_foot"/>
  </joint>
  <!-- Links -->
  <!-- abad link -->
  <link name="rf_abad_link">
    <inertial>
      <origin rpy="0 0 0" xyz="-0.0012806 4.3563E-08 0.049958"/>
      <mass value="0.92607"/>
      <inertia ixx="0.00098647" ixy="-7.0392E-11" ixz="6.4987E-06" iyy="0.00071554" iyz="1.2357E-10" izz="0.00065157"/>
    </inertial>
    <visual>
      <origin rpy="0 0  0 " xyz="0 0 0"/>
      <geometry>
        <mesh filename="package://siriusmid_description/meshes/rf_abad_link.STL"/>
      </geometry>
      <material name="Black"/>
    </visual>
    <collision>
      <origin rpy="0 0 0 " xyz="0 0 0"/>
      <geometry>
        <mesh filename="package://siriusmid_description/meshes/rf_abad_link.STL"/>
      </geometry>
    </collision>
  </link>
  <!-- name: lf,lr,rf,rr -->
  <link name="rf_hip_link">
    <inertial>
      <origin rpy="0 0 0" xyz="0.027042 -1.7816E-10 0.028552"/>
      <mass value="1.22"/>
      <inertia ixx="0.001198" ixy="4.6672E-11" ixz="0.00095291" iyy="0.0068604" iyz="2.0712E-12" izz="0.0068553"/>
    </inertial>
    <visual>
      <origin rpy="0 0  0 " xyz="0 0 0"/>
      <geometry>
        <mesh filename="package://siriusmid_description/meshes/rf_hip_link.STL"/>
      </geometry>
      <material name="GreenSky"/>
    </visual>
    <collision>
      <origin rpy="0 0 0 " xyz="0 0 0"/>
      <geometry>
        <mesh filename="package://siriusmid_description/meshes/rf_hip_link.STL"/>
      </geometry>
    </collision>
  </link>
  <!-- Lower leg link -->
  <!-- name: lf,lr,rf,rr -->
  <link name="rf_knee_link">
    <inertial>
      <origin rpy="0 0 0" xyz="0.11612 -0.0066095 -4.5982E-08"/>
      <mass value="0.19509"/>
      <inertia ixx="0.00010142" ixy="-0.00027114" ixz="2.9242E-09" iyy="0.0024964" iyz="2.6632E-09" izz="0.0025805"/>
    </inertial>
    <visual>
      <origin rpy="0 0  0 " xyz="0 0 0"/>
      <geometry>
        <mesh filename="package://siriusmid_description/meshes/rf_knee_link.STL"/>
      </geometry>
      <material name="Blue"/>
    </visual>
    <collision>
      <origin rpy="0 0 0 " xyz="0 0 0"/>
      <geometry>
        <mesh filename="package://siriusmid_description/meshes/rf_knee_link.STL"/>
      </geometry>
    </collision>
  </link>
  <!-- Links -->
  <!-- Foot link -->
  <link name="rf_foot">
    <collision>
      <origin rpy="0 0 0" xyz="0 0 0"/>
      <geometry>
        <sphere radius="0.02175"/>
      </geometry>
    </collision>
    <visual>
      <geometry>
        <sphere radius="0.02175"/>
      </geometry>
      <material name="Red"/>
    </visual>
    <inertial>
      <origin rpy="0 0 0" xyz="0 0 0"/>
      <mass value="0.003"/>
      <inertia ixx="0." ixy="0" ixz="0" iyy="0" iyz="0" izz="0"/>
    </inertial>
  </link>
  <!-- Hip assembly -->
  <transmission name="rf_abad_trans">
    <type>transmission_interface/SimpleTransmission</type>
    <joint name="rf_abad_joint">
      <hardwareInterface>hardware_interface/EffortJointInterface</hardwareInterface>
    </joint>
    <actuator name="rf_haa_motor">
      <mechanicalReduction>1</mechanicalReduction>
    </actuator>
  </transmission>
  <!-- Upper leg -->
  <transmission name="rf_hip_trans">
    <type>transmission_interface/SimpleTransmission</type>
    <joint name="rf_hip_joint">
      <hardwareInterface>hardware_interface/EffortJointInterface</hardwareInterface>
    </joint>
    <actuator name="rf_hip_motor">
      <mechanicalReduction>1</mechanicalReduction>
    </actuator>
  </transmission>
  <!-- Lower leg -->
  <transmission name="rf_knee_trans">
    <type>transmission_interface/SimpleTransmission</type>
    <joint name="rf_knee_joint">
      <hardwareInterface>hardware_interface/EffortJointInterface</hardwareInterface>
    </joint>
    <actuator name="rf_knee_motor">
      <mechanicalReduction>1</mechanicalReduction>
    </actuator>
  </transmission>

    <joint name="rr_abad_joint" type="revolute">
    <parent link="body_link"/>
    <child link="rr_abad_link"/>
    <origin rpy="1.5708 0 -1.5708" xyz="-0.216 -0.055 0"/>
    <axis xyz="0 0 -1"/>
    <limit effort="25" lower="-2.88" upper="2.88" velocity="15"/>
    <!-- soft limits  keep the motor in safety mode-->
    <safety_controller k_position="500" k_velocity="5" soft_lower_limit="-2.78" soft_upper_limit="2.78"/>
  </joint>
  <!-- Upper leg joint -->
  <joint name="rr_hip_joint" type="revolute">
    <parent link="rr_abad_link"/>
    <child link="rr_hip_link"/>
    <origin rpy="-1.5708 0 -1.5708" xyz="0.09355 0 0.052"/>
    <axis xyz="0 0 1"/>
    <limit effort="25" lower="-2.88" upper="2.88" velocity="15"/>
    <!-- soft limits  keep the motor in safety mode-->
    <safety_controller k_position="500" k_velocity="5" soft_lower_limit="-2.78" soft_upper_limit="2.78"/>
  </joint>
  <!-- Lower leg joint -->
  <joint name="rr_knee_joint" type="revolute">
    <parent link="rr_hip_link"/>
    <child link="rr_knee_link"/>
    <origin rpy="0 0 0" xyz="0.269 0 0"/>
    <axis xyz="0 0 -1"/>
    <limit effort="25" lower="-2.88" upper="2.88" velocity="15"/>
    <!-- soft limits  keep the motor in safety mode-->
    <safety_controller k_position="500" k_velocity="5" soft_lower_limit="-2.78" soft_upper_limit="2.78"/>
  </joint>
  <!-- foot joint-->
  <joint name="rr_foot_joint" type="fixed">
    <origin rpy="1.57079632679 0 -1.57079632679" xyz="0.271 0 0"/>
    <parent link="rr_knee_link"/>
    <child link="rr_foot"/>
  </joint>

  <!-- Joints -->
  <!-- abad assembly joint -->
  <joint name="lr_abad_joint" type="revolute">
    <parent link="body_link"/>
    <child link="lr_abad_link"/>
    <origin rpy="-1.5708 0 1.5708" xyz="-0.216 0.055 0"/>
    <axis xyz="0 0 -1"/>
    <limit effort="25" lower="-2.88" upper="2.88" velocity="15"/>
    <!-- soft limits  keep the motor in safety mode-->
    <safety_controller k_position="500" k_velocity="5" soft_lower_limit="-2.78" soft_upper_limit="2.78"/>
  </joint>
  <!-- Upper leg joint -->
  <joint name="lr_hip_joint" type="revolute">
    <parent link="lr_abad_link"/>
    <child link="lr_hip_link"/>
    <origin rpy="-1.5708 0 1.5708" xyz="0.09355 0 0.052"/>
    <axis xyz="0 0 1"/>
    <limit effort="25" lower="-2.88" upper="2.88" velocity="15"/>
    <!-- soft limits  keep the motor in safety mode-->
    <safety_controller k_position="500" k_velocity="5" soft_lower_limit="-2.78" soft_upper_limit="2.78"/>
  </joint>
  <!-- Lower leg joint -->
  <joint name="lr_knee_joint" type="revolute">
    <parent link="lr_hip_link"/>
    <child link="lr_knee_link"/>
    <origin rpy="0 0 0" xyz="0.269 0 0"/>
    <axis xyz="0 0 -1"/>
    <limit effort="25" lower="-2.88" upper="2.88" velocity="15"/>
    <!-- soft limits  keep the motor in safety mode-->
    <safety_controller k_position="500" k_velocity="5" soft_lower_limit="-2.78" soft_upper_limit="2.78"/>
  </joint>
  <!-- foot joint-->
  <joint name="lr_foot_joint" type="fixed">
    <origin rpy="1.57079632679 0 -1.57079632679" xyz="0.271 0 0"/>
    <parent link="lr_knee_link"/>
    <child link="lr_foot"/>
  </joint>
  <!-- Links -->
  <!-- abad link -->
  <link name="lr_abad_link">
    <inertial>
      <origin rpy="0 0 0" xyz="-0.0012806 4.3563E-08 0.049958"/>
      <mass value="0.92607"/>
      <inertia ixx="0.00098647" ixy="-7.0392E-11" ixz="6.4987E-06" iyy="0.00071554" iyz="1.2357E-10" izz="0.00065157"/>
    </inertial>
    <visual>
      <origin rpy="0 0  0 " xyz="0 0 0"/>
      <geometry>
        <mesh filename="package://siriusmid_description/meshes/lr_abad_link.STL"/>
      </geometry>
      <material name="Black"/>
    </visual>
    <collision>
      <origin rpy="0 0 0 " xyz="0 0 0"/>
      <geometry>
        <mesh filename="package://siriusmid_description/meshes/lr_abad_link.STL"/>
      </geometry>
    </collision>
  </link>
  <!-- name: lf,lr,rf,rr -->
  <link name="lr_hip_link">
    <inertial>
      <origin rpy="0 0 0" xyz="0.027042 -1.7816E-10 0.028552"/>
      <mass value="1.22"/>
      <inertia ixx="0.001198" ixy="4.6672E-11" ixz="0.00095291" iyy="0.0068604" iyz="2.0712E-12" izz="0.0068553"/>
    </inertial>
    <visual>
      <origin rpy="0 0  0 " xyz="0 0 0"/>
      <geometry>
        <mesh filename="package://siriusmid_description/meshes/lr_hip_link.STL"/>
      </geometry>
      <material name="GreenSky"/>
    </visual>
    <collision>
      <origin rpy="0 0 0 " xyz="0 0 0"/>
      <geometry>
        <mesh filename="package://siriusmid_description/meshes/lr_hip_link.STL"/>
      </geometry>
    </collision>
  </link>
  <!-- Lower leg link -->
  <!-- name: lf,lr,rf,rr -->
  <link name="lr_knee_link">
    <inertial>
      <origin rpy="0 0 0" xyz="0.11612 -0.0066095 -4.5982E-08"/>
      <mass value="0.19509"/>
      <inertia ixx="0.00010142" ixy="-0.00027114" ixz="2.9242E-09" iyy="0.0024964" iyz="2.6632E-09" izz="0.0025805"/>
    </inertial>
    <visual>
      <origin rpy="0 0  0 " xyz="0 0 0"/>
      <geometry>
        <mesh filename="package://siriusmid_description/meshes/lr_knee_link.STL"/>
      </geometry>
      <material name="Blue"/>
    </visual>
    <collision>
      <origin rpy="0 0 0 " xyz="0 0 0"/>
      <geometry>
        <mesh filename="package://siriusmid_description/meshes/lr_knee_link.STL"/>
      </geometry>
    </collision>
  </link>
  <!-- Links -->
  <!-- Foot link -->
  <link name="lr_foot">
    <collision>
      <origin rpy="0 0 0" xyz="0 0 0"/>
      <geometry>
        <sphere radius="0.02175"/>
      </geometry>
    </collision>
    <visual>
      <geometry>
        <sphere radius="0.02175"/>
      </geometry>
      <material name="Red"/>
    </visual>
    <inertial>
      <origin rpy="0 0 0" xyz="0 0 0"/>
      <mass value="0.003"/>
      <inertia ixx="0." ixy="0" ixz="0" iyy="0" iyz="0" izz="0"/>
    </inertial>
  </link>
  <!-- Hip assembly -->
  <transmission name="lr_abad_trans">
    <type>transmission_interface/SimpleTransmission</type>
    <joint name="lr_abad_joint">
      <hardwareInterface>hardware_interface/EffortJointInterface</hardwareInterface>
    </joint>
    <actuator name="lr_haa_motor">
      <mechanicalReduction>1</mechanicalReduction>
    </actuator>
  </transmission>
  <!-- Upper leg -->
  <transmission name="lr_hip_trans">
    <type>transmission_interface/SimpleTransmission</type>
    <joint name="lr_hip_joint">
      <hardwareInterface>hardware_interface/EffortJointInterface</hardwareInterface>
    </joint>
    <actuator name="lr_hip_motor">
      <mechanicalReduction>1</mechanicalReduction>
    </actuator>
  </transmission>
  <!-- Lower leg -->
  <transmission name="lr_knee_trans">
    <type>transmission_interface/SimpleTransmission</type>
    <joint name="lr_knee_joint">
      <hardwareInterface>hardware_interface/EffortJointInterface</hardwareInterface>
    </joint>
    <actuator name="lr_knee_motor">
      <mechanicalReduction>1</mechanicalReduction>
    </actuator>
  </transmission>
  <!-- Joints -->
  <!-- abad assembly joint -->
  <!-- Links -->
  <!-- abad link -->
  <link name="rr_abad_link">
    <inertial>
      <origin rpy="0 0 0" xyz="-0.0012806 4.3563E-08 0.049958"/>
      <mass value="0.92607"/>
      <inertia ixx="0.00098647" ixy="-7.0392E-11" ixz="6.4987E-06" iyy="0.00071554" iyz="1.2357E-10" izz="0.00065157"/>
    </inertial>
    <visual>
      <origin rpy="0 0  0 " xyz="0 0 0"/>
      <geometry>
        <mesh filename="package://siriusmid_description/meshes/rr_abad_link.STL"/>
      </geometry>
      <material name="Black"/>
    </visual>
    <collision>
      <origin rpy="0 0 0 " xyz="0 0 0"/>
      <geometry>
        <mesh filename="package://siriusmid_description/meshes/rr_abad_link.STL"/>
      </geometry>
    </collision>
  </link>
  <!-- name: lf,lr,rf,rr -->
  <link name="rr_hip_link">
    <inertial>
      <origin rpy="0 0 0" xyz="0.027042 -1.7816E-10 0.028552"/>
      <mass value="1.22"/>
      <inertia ixx="0.001198" ixy="4.6672E-11" ixz="0.00095291" iyy="0.0068604" iyz="2.0712E-12" izz="0.0068553"/>
    </inertial>
    <visual>
      <origin rpy="0 0  0 " xyz="0 0 0"/>
      <geometry>
        <mesh filename="package://siriusmid_description/meshes/rr_hip_link.STL"/>
      </geometry>
      <material name="GreenSky"/>
    </visual>
    <collision>
      <origin rpy="0 0 0 " xyz="0 0 0"/>
      <geometry>
        <mesh filename="package://siriusmid_description/meshes/rr_hip_link.STL"/>
      </geometry>
    </collision>
  </link>
  <!-- Lower leg link -->
  <!-- name: lf,lr,rf,rr -->
  <link name="rr_knee_link">
    <inertial>
      <origin rpy="0 0 0" xyz="0.11612 -0.0066095 -4.5982E-08"/>
      <mass value="0.19509"/>
      <inertia ixx="0.00010142" ixy="-0.00027114" ixz="2.9242E-09" iyy="0.0024964" iyz="2.6632E-09" izz="0.0025805"/>
    </inertial>
    <visual>
      <origin rpy="0 0  0 " xyz="0 0 0"/>
      <geometry>
        <mesh filename="package://siriusmid_description/meshes/rr_knee_link.STL"/>
      </geometry>
      <material name="Blue"/>
    </visual>
    <collision>
      <origin rpy="0 0 0 " xyz="0 0 0"/>
      <geometry>
        <mesh filename="package://siriusmid_description/meshes/rr_knee_link.STL"/>
      </geometry>
    </collision>
  </link>
  <!-- Links -->
  <!-- Foot link -->
  <link name="rr_foot">
    <collision>
      <origin rpy="0 0 0" xyz="0 0 0"/>
      <geometry>
        <sphere radius="0.02175"/>
      </geometry>
    </collision>
    <visual>
      <geometry>
        <sphere radius="0.02175"/>
      </geometry>
      <material name="Red"/>
    </visual>
    <inertial>
      <origin rpy="0 0 0" xyz="0 0 0"/>
      <mass value="0.003"/>
      <inertia ixx="0." ixy="0" ixz="0" iyy="0" iyz="0" izz="0"/>
    </inertial>
  </link>
  <!-- Hip assembly -->
  <transmission name="rr_abad_trans">
    <type>transmission_interface/SimpleTransmission</type>
    <joint name="rr_abad_joint">
      <hardwareInterface>hardware_interface/EffortJointInterface</hardwareInterface>
    </joint>
    <actuator name="rr_haa_motor">
      <mechanicalReduction>1</mechanicalReduction>
    </actuator>
  </transmission>
  <!-- Upper leg -->
  <transmission name="rr_hip_trans">
    <type>transmission_interface/SimpleTransmission</type>
    <joint name="rr_hip_joint">
      <hardwareInterface>hardware_interface/EffortJointInterface</hardwareInterface>
    </joint>
    <actuator name="rr_hip_motor">
      <mechanicalReduction>1</mechanicalReduction>
    </actuator>
  </transmission>
  <!-- Lower leg -->
  <transmission name="rr_knee_trans">
    <type>transmission_interface/SimpleTransmission</type>
    <joint name="rr_knee_joint">
      <hardwareInterface>hardware_interface/EffortJointInterface</hardwareInterface>
    </joint>
    <actuator name="rr_knee_motor">
      <mechanicalReduction>1</mechanicalReduction>
    </actuator>
  </transmission>
</robot>

